<?xml version="1.0" ?>

<robot name="myboat"  xmlns:xacro="http://www.ros.org/wiki/xacro">

  <!-- Constants for robot dimensions -->
  <xacro:property name="PI" value="3.1415926535897931"/>

  <!-- Import all Gazebo-customization elements, including Gazebo colors -->
  <xacro:include filename="$(find boot0_description)/urdf/boot0.gazebo" />
  <!-- Import Rviz colors -->
  <xacro:include filename="$(find boot0_description)/urdf/materials.xacro" />


    
  <joint name="body_arm" type="revolute">
    <parent link="myboat__body"/>
    <child link="myboat__arm"/>
    <origin rpy="-1.45000e-03 -1.54681e+00  3.75000e-03" xyz="0.02714 -0.00665  1.9954"/>
    <axis xyz="8.0000e-05  9.9999e-01 -2.2500e-03"/>
    <limit effort="200.0" lower="-1" upper="1" velocity="1.0"/>
  </joint>
  <joint name="arm_blad" type="revolute">
    <parent link="myboat__arm"/>
    <child link="myboat__blad"/>
    <origin rpy="-3.13788  0.91639 -3.13874" xyz="-0.03048 -0.03639  2.64237"/>
    <axis xyz="0 1 0"/>
    <limit effort="10.0" lower="-1.57" upper="1.57" velocity="1.0"/>
  </joint>
  <joint name="base_body" type="revolute">
    <parent link="base_link"/>
    <child link="myboat__body"/>
    <origin rpy="0.e+00  0.e+00 -4.e-05" xyz="-0.98209 -0.1049   0.15209"/>
    <axis xyz="-4.e-05  1.e+00  0.e+00"/>
    <limit effort="200.0" lower="-1" upper="1" velocity="1.0"/>
  </joint>

  <link name="base_link"/> 
  <!-- Dummy for gazebo   -->
  <joint name="dummy" type="fixed">
    <parent link="base_link"/>
    <child link="myboat__base"/>
  </joint>

  <link name="myboat__base">    
    <inertial>
      <mass value="15"/>
      <origin rpy="0 0 0" xyz="0 0 0"/>
      <inertia ixx="3.0" ixy="0" ixz="0" iyy="120" iyz="0" izz="120"/>
    </inertial>
    <collision name="myboat__collision">
      <origin rpy="0 0 0" xyz="-1.06112 -0.1246   0.1"/>
      <geometry>
        <box size="3.0 0.663318 0.197068"/>
      </geometry>
    </collision>
    <visual name="myboat__visual">
      <origin rpy="0 0 0" xyz="-1.06112 -0.1246   0.1"/>
      <geometry>
        <box size="3.0 0.663318 0.197068"/>
      </geometry>
    </visual>
  </link>
  <link name="myboat__body">
    <inertial>
      <mass value="60.0"/>
      <origin rpy="0 0 0" xyz="0 0 0"/>
      <inertia ixx="120" ixy="0" ixz="0" iyy="120" iyz="0" izz="0.33"/>
    </inertial>
    <collision name="myboat__collision">
      <origin rpy="0 0 0" xyz="0   0   0.97"/>
      <geometry>
        <box size="0.100516 0.036549 1.95488"/>
      </geometry>
    </collision>
    <visual name="myboat__visual">
      <origin rpy="0 0 0" xyz="0   0   0.97"/>
      <geometry>
        <box size="0.100516 0.036549 1.95488"/>
      </geometry>
    </visual>
  </link>
  <link name="myboat__blad">
    <inertial>
      <mass value="1.0"/>
      <origin rpy="0 0 0" xyz="0 0 0"/>
      <inertia ixx="1.85" ixy="0" ixz="0" iyy="1.85" iyz="0" izz="0.4"/>
    </inertial>
    <collision name="myboat__collision">
      <origin rpy="0 0 0" xyz="0    0   -0.05"/>
      <geometry>
        <box size="0.695693 0.648073 0.108244"/>
      </geometry>
    </collision>
    <visual name="myboat__visual">
      <origin rpy="0 0 0" xyz="0    0   -0.05"/>
      <geometry>
        <box size="0.695693 0.648073 0.108244"/>
      </geometry>
    </visual>
  </link>
  <link name="myboat__arm">
    <inertial>
      <mass value="1.0"/>
      <origin rpy="0 0 0" xyz="0 0 0"/>
      <inertia ixx="0.4" ixy="0" ixz="0" iyy="0.4" iyz="0" izz="0.0013"/>
    </inertial>
    <collision name="myboat__collision">
      <origin rpy="0 0 0" xyz="0  0  1.3"/>
      <geometry>
        <cylinder length="1.97792" radius="0.05655"/>
      </geometry>
    </collision>
    <visual name="myboat__visual">
      <origin rpy="0 0 0" xyz="0  0  1.3"/>
      <geometry>
        <cylinder length="2.5" radius="0.05655"/>
      </geometry>
    </visual>
  </link>

  <transmission name="tran1">
    <type>transmission_interface/SimpleTransmission</type>
    <joint name="base_body">
      <hardwareInterface>hardware_interface/EffortJointInterface</hardwareInterface>
    </joint>
    <actuator name="motor1">
      <mechanicalReduction>1</mechanicalReduction>
    </actuator>
  </transmission>

  <transmission name="tran2">
    <type>transmission_interface/SimpleTransmission</type>
    <joint name="body_arm">
      <hardwareInterface>hardware_interface/EffortJointInterface</hardwareInterface>
    </joint>
    <actuator name="motor2">
      <mechanicalReduction>1</mechanicalReduction>
    </actuator>
  </transmission>

  <transmission name="tran3">
    <type>transmission_interface/SimpleTransmission</type>
    <joint name="arm_blad">
      <hardwareInterface>hardware_interface/EffortJointInterface</hardwareInterface>
    </joint>
    <actuator name="motor2">
      <mechanicalReduction>1</mechanicalReduction>
    </actuator>
  </transmission>




</robot>
