<sdf version='1.6'>
  <model name='myboat'>
    <link name='base_link'>
      <pose frame=''>0 0 0 0 -0 0</pose>
      <inertial>
        <pose frame=''>-1 -0.12 0.1 0 -0 0</pose>
        <mass>15</mass>
        <inertia>
          <ixx>0.6</ixx>
          <ixy>0</ixy>
          <ixz>0</ixz>
          <iyy>11</iyy>
          <iyz>2.77556e-17</iyz>
          <izz>11.8</izz>
        </inertia>
      </inertial>
      <collision name='base_link_fixed_joint_lump__myboat__base_collision'>
        <pose frame=''>-1 -0.12 0.1 0 -0 0</pose>
        <geometry>
          <box>
            <size>3 0.663318 0.197068</size>
          </box>
        </geometry>
        <surface>
          <contact>
            <ode/>
          </contact>
          <friction>
            <ode/>
          </friction>
        </surface>
      </collision>
      <visual name='base_link_fixed_joint_lump__myboat__base_visual'>
        <pose frame=''>-1.06112 -0.1246 0.1 0 -0 0</pose>
        <geometry>
          <box>
            <size>3 0.663318 0.197068</size>
          </box>
        </geometry>
        <material>
          <script>
            <name>Gazebo/Orange</name>
            <uri>file://media/materials/scripts/gazebo.material</uri>
          </script>
        </material>
      </visual>
      <gravity>1</gravity>
      <velocity_decay/>
    </link>
    <link name='myboat__body'>
      <pose frame=''>-0.98209 -0.1049 0.15209 0 0 -4e-05</pose>
      <inertial>
        <pose frame=''>0 0 0.97 0 -0 0</pose>
        <mass>60</mass>
        <inertia>
          <ixx>19</ixx>
          <ixy>0</ixy>
          <ixz>0</ixz>
          <iyy>19</iyy>
          <iyz>0</iyz>
          <izz>0.056</izz>
        </inertia>
      </inertial>
      <collision name='myboat__body_collision'>
        <pose frame=''>0 0 0.97 0 -0 0</pose>
        <geometry>
          <box>
            <size>0.100516 0.036549 1.95488</size>
          </box>
        </geometry>
        <surface>
          <contact>
            <ode/>
          </contact>
          <friction>
            <ode>
              <mu>0.2</mu>
              <mu2>0.2</mu2>
            </ode>
          </friction>
        </surface>
      </collision>
      <visual name='myboat__body_visual'>
        <pose frame=''>0 0 0.97 0 -0 0</pose>
        <geometry>
          <box>
            <size>0.100516 0.036549 1.95488</size>
          </box>
        </geometry>
        <material>
          <script>
            <name>Gazebo/Black</name>
            <uri>file://media/materials/scripts/gazebo.material</uri>
          </script>
        </material>
      </visual>
      <gravity>1</gravity>
      <velocity_decay/>
    </link>
    <joint name='base_body' type='revolute'>
      <child>myboat__body</child>
      <parent>base_link</parent>
      <axis>
        <xyz>4e-05 1 0</xyz>
        <limit>
          <lower>-1.4</lower>
          <upper>1.4</upper>
          <effort>2000</effort>
          <velocity>1</velocity>
        </limit>
        <dynamics>
          <spring_reference>0</spring_reference>
          <spring_stiffness>0</spring_stiffness>
        </dynamics>
        <use_parent_model_frame>1</use_parent_model_frame>
      </axis>
      <physics>
        <provide_feedback>1</provide_feedback>
        <ode>
          <provide_feedback>1</provide_feedback>
          <limit>
            <cfm>0</cfm>
            <erp>0.2</erp>
          </limit>
        </ode>
      </physics>
      <sensor name='bb_force_torque' type='force_torque'>
        <update_rate>30</update_rate>
      </sensor>
    </joint>
    <link name='myboat__arm'>
      <pose frame=''>-0.95495 -0.111551 2.14749 -0.00145 -1.54681 0.00371</pose>
      <inertial>
        <pose frame=''>0 0 1.3 0 -0 0</pose>
        <mass>1</mass>
        <inertia>
          <ixx>0.32</ixx>
          <ixy>0</ixy>
          <ixz>0</ixz>
          <iyy>0.32</iyy>
          <iyz>0</iyz>
          <izz>0.0016</izz>
        </inertia>
      </inertial>
      <collision name='myboat__arm_collision'>
        <pose frame=''>0 0 1.3 0 -0 0</pose>
        <geometry>
          <cylinder>
            <length>1.97792</length>
            <radius>0.05655</radius>
          </cylinder>
        </geometry>
        <surface>
          <contact>
            <ode/>
          </contact>
          <friction>
            <ode>
              <mu>0.2</mu>
              <mu2>0.2</mu2>
            </ode>
          </friction>
        </surface>
      </collision>
      <visual name='myboat__arm_visual'>
        <pose frame=''>0 0 1.3 0 -0 0</pose>
        <geometry>
          <cylinder>
            <length>2.5</length>
            <radius>0.05655</radius>
          </cylinder>
        </geometry>
        <material>
          <script>
            <name>Gazebo/Orange</name>
            <uri>file://media/materials/scripts/gazebo.material</uri>
          </script>
        </material>
      </visual>
      <gravity>1</gravity>
      <velocity_decay/>
    </link>
    <joint name='body_arm' type='revolute'>
      <child>myboat__arm</child>
      <parent>myboat__body</parent>
      <axis>
        <xyz>-0.00226 0.999997 -3.5e-05</xyz>
        <limit>
          <lower>-1.4</lower>
          <upper>1.4</upper>
          <effort>200</effort>
          <velocity>1</velocity>
        </limit>
        <dynamics>
          <spring_reference>0</spring_reference>
          <spring_stiffness>0</spring_stiffness>
        </dynamics>
        <use_parent_model_frame>1</use_parent_model_frame>
      </axis>
      <physics>
        <provide_feedback>1</provide_feedback>
        <ode>
          <provide_feedback>1</provide_feedback>
          <limit>
            <cfm>0</cfm>
            <erp>0.2</erp>
          </limit>
        </ode>
      </physics>
      <sensor name='ba_force_torque' type='force_torque'>
        <update_rate>30</update_rate>
      </sensor>
    </joint>
    <link name='myboat__blad'>
      <pose frame=''>-3.5972 -0.153913 2.18039 5e-06 0.678389 2e-06</pose>
      <inertial>
        <pose frame=''>0 0 -0.05 0 -0 0</pose>
        <mass>1</mass>
        <inertia>
          <ixx>0.34</ixx>
          <ixy>0</ixy>
          <ixz>0</ixz>
          <iyy>0.34</iyy>
          <iyz>0</iyz>
          <izz>0.73</izz>
        </inertia>
      </inertial>
      <collision name='myboat__blad_collision'>
        <pose frame=''>0 0 -0.05 0 -0 0</pose>
        <geometry>
          <box>
            <size>0.695693 0.648073 0.108244</size>
          </box>
        </geometry>
        <surface>
          <contact>
            <ode/>
          </contact>
          <friction>
            <ode>
              <mu>0.2</mu>
              <mu2>0.2</mu2>
            </ode>
          </friction>
        </surface>
      </collision>
      <visual name='myboat__blad_visual'>
        <pose frame=''>0 0 -0.05 0 -0 0</pose>
        <geometry>
          <box>
            <size>0.695693 0.648073 0.108244</size>
          </box>
        </geometry>
        <material>
          <script>
            <name>Gazebo/Orange</name>
            <uri>file://media/materials/scripts/gazebo.material</uri>
          </script>
        </material>
      </visual>
      <gravity>1</gravity>
      <velocity_decay/>
    </link>
    <joint name='arm_blad' type='revolute'>
      <child>myboat__blad</child>
      <parent>myboat__arm</parent>
      <axis>
        <xyz>1e-06 1 4e-06</xyz>
        <limit>
          <lower>-1.4</lower>
          <upper>1.4</upper>
          <effort>10</effort>
          <velocity>1</velocity>
        </limit>
        <dynamics>
          <spring_reference>0</spring_reference>
          <spring_stiffness>0</spring_stiffness>
        </dynamics>
        <use_parent_model_frame>1</use_parent_model_frame>
      </axis>
      <physics>
        <provide_feedback>1</provide_feedback>
        <ode>
          <provide_feedback>1</provide_feedback>
          <limit>
            <cfm>0</cfm>
            <erp>0.2</erp>
          </limit>
        </ode>
      </physics>
      <sensor name='ab_force_torque' type='force_torque'>
        <update_rate>30</update_rate>
      </sensor>
    </joint>
    <self_collide>1</self_collide>
    <plugin name='gazebo_ros_control' filename='libgazebo_ros_control.so'>
      <robotNamespace>/boot0</robotNamespace>
      <robotSimType>gazebo_ros_control/DefaultRobotHWSim</robotSimType>
    </plugin>
    <static>0</static>
    <plugin name='bb_sensor' filename='libgazebo_ros_ft_sensor.so'>
      <updateRate>10.0</updateRate>
      <topicName>bb_sensor_topic</topicName>
      <jointName>base_body</jointName>
    </plugin>
    <plugin name='ba_sensor' filename='libgazebo_ros_ft_sensor.so'>
      <updateRate>10.0</updateRate>
      <topicName>ba_sensor_topic</topicName>
      <jointName>body_arm</jointName>
    </plugin>
    <plugin name='ab_sensor' filename='libgazebo_ros_ft_sensor.so'>
      <updateRate>10.0</updateRate>
      <topicName>ab_sensor_topic</topicName>
      <jointName>arm_blad</jointName>
    </plugin>
  </model>
</sdf>
