<?xml version="1.0" ?>

<robot name="myboat"  xmlns:xacro="http://www.ros.org/wiki/xacro">

  <!-- Constants for robot dimensions -->
  <xacro:property name="PI" value="3.1415926535897931"/>

  <!-- Import all Gazebo-customization elements, including Gazebo colors -->
  <xacro:include filename="$(find boot0_description)/urdf/boot0.gazebo" />
  <!-- Import Rviz colors -->
  <xacro:include filename="$(find boot0_description)/urdf/materials.xacro" />


    
  <joint name="body_arm" type="revolute">
    <parent link="myboat__body"/>
    <child link="myboat__arm"/>
    <origin rpy="-1.45000e-03 -1.54681e+00  3.75000e-03" xyz="0.02714 -0.00665  1.9954"/>
    <axis xyz="0 1 0"/>
    <limit effort="200.0" lower="-1.4" upper="1.4" velocity="1.0"/>
  </joint>
  <joint name="arm_blad" type="revolute">
    <parent link="myboat__arm"/>
    <child link="myboat__blad"/>
    <origin rpy="-3.13788  0.91639 -3.13874" xyz="-0.03048 -0.03639  2.64237"/>
    <axis xyz="0 1 0"/>
    <limit effort="200.0" lower="-1.4" upper="1.4" velocity="1.0"/>
  </joint>
  <joint name="base_body" type="revolute">
    <parent link="base_link"/>
    <child link="myboat__body"/>
    <origin rpy="0.e+00  0.e+00 -4.e-05" xyz="-0.1 -0.1   0.15209"/>
    <axis xyz="0 1 0"/>
    <limit effort="2000.0" lower="-1.4" upper="1.4" velocity="1.0"/>
  </joint>

  <link name="base_link"/> 
  <!-- Dummy for gazebo   -->
  <joint name="dummy" type="fixed">
    <parent link="base_link"/>
    <child link="myboat__base"/>
  </joint>

  <link name="myboat__base">    
    <inertial>
      <mass value="15"/>
      <origin rpy="0 0 0" xyz="0.0 0.0 0.1"/>
      <inertia ixx="0.6" ixy="0" ixz="0" iyy="11" iyz="0" izz="11.8"/>
    </inertial>
    <collision>
      <origin rpy="0 0 0" xyz="0.0 0.0   0.1"/>
      <geometry>
        <box size="3.0 0.7 0.2"/>
      </geometry>
    </collision>
    <visual>
      <origin rpy="0 0 0" xyz="0.0 0.0  0.1"/>
      <geometry>
        <box size="3.0 0.7 0.2"/>
      </geometry>
    </visual>
  </link>
  <link name="myboat__body">
    <inertial>
      <mass value="60.0"/>
      <origin rpy="0 0 0" xyz="0 0 0.97"/>
      <inertia ixx="19" ixy="0" ixz="0" iyy="19" iyz="0" izz="0.056"/>	   
    </inertial>
    <collision>
      <origin rpy="0 0 0" xyz="0   0   0.97"/>
      <geometry>
        <box size="0.100516 0.036549 1.95488"/>
      </geometry>
    </collision>
    <visual>
      <origin rpy="0 0 0" xyz="0   0   0.97"/>
      <geometry>
        <box size="0.100516 0.036549 1.95488"/>
      </geometry>
    </visual>
  </link>
  <link name="myboat__blad">
    <inertial>
      <mass value="1.0"/>
      <origin rpy="0 0 0" xyz="0 0 -0.05"/>
      <inertia ixx="0.34" ixy="0" ixz="0" iyy="0.34" iyz="0" izz="0.73"/>
    </inertial>
    <collision>
      <origin rpy="0 0 0" xyz="0    0   -0.05"/>
      <geometry>
        <box size="0.695693 0.648073 0.108244"/>
      </geometry>
    </collision>
    <visual>
      <origin rpy="0 0 0" xyz="0    0   -0.05"/>
      <geometry>
        <box size="0.695693 0.648073 0.108244"/>
      </geometry>
    </visual>
  </link>
  <link name="myboat__arm">
    <inertial>
      <mass value="1.0"/>
      <origin rpy="0 0 0" xyz="0 0 1.3"/>
      <inertia ixx="0.32" ixy="0" ixz="0" iyy="0.32" iyz="0" izz="0.0016"/>
    </inertial>
    <collision>
      <origin rpy="0 0 0" xyz="0  0  1.3"/>
      <geometry>
        <cylinder length="1.97792" radius="0.05655"/>
      </geometry>
    </collision>
    <visual>
      <origin rpy="0 0 0" xyz="0  0  1.3"/>
      <geometry>
        <cylinder length="2.5" radius="0.05655"/>
      </geometry>
    </visual>
  </link>

  <transmission name="tran1">
    <type>transmission_interface/SimpleTransmission</type>
    <joint name="base_body">
      <hardwareInterface>hardware_interface/EffortJointInterface</hardwareInterface>
    </joint>
    <actuator name="motor1">
      <mechanicalReduction>1</mechanicalReduction>
    </actuator>
  </transmission>

  <transmission name="tran2">
    <type>transmission_interface/SimpleTransmission</type>
    <joint name="body_arm">
      <hardwareInterface>hardware_interface/EffortJointInterface</hardwareInterface>
    </joint>
    <actuator name="motor2">
      <mechanicalReduction>1</mechanicalReduction>
    </actuator>
  </transmission>

  <transmission name="tran3">
    <type>transmission_interface/SimpleTransmission</type>
    <joint name="arm_blad">
      <hardwareInterface>hardware_interface/EffortJointInterface</hardwareInterface>
    </joint>
    <actuator name="motor2">
      <mechanicalReduction>1</mechanicalReduction>
    </actuator>
  </transmission>




</robot>
