<?xml version="1.0" ?>

<robot name="myboat"  xmlns:xacro="http://www.ros.org/wiki/xacro">

  <!-- Constants for robot dimensions -->


  <!-- Import all Gazebo-customization elements, including Gazebo colors -->
  <xacro:include filename="$(find boot1_description)/urdf/boot1.gazebo" />
  <!-- Import Rviz colors -->
  <xacro:include filename="$(find boot1_description)/urdf/materials.xacro" />

    
  <joint name="starboard_rowlock_joint" type="revolute">
    <parent link="skiff"/>
    <child link="starboard_rowlock"/>
    <origin rpy="0.0  0.0 0.0" xyz="0.0 0.8 0.72"/>
    <axis xyz="0 0 1"/>
    <limit effort="1000.0" lower="-1.4" upper="1.4" velocity="1.0"/>
  </joint>


  <link name="world"/> 
  <!-- Dummy for gazebo   -->
  <joint name="dummy" type="fixed">
    <parent link="world"/>
    <child link="skiff"/>
  </joint>

  <link name="skiff">    
    <inertial>
      <mass value="75"/>   <!-- 15 + 60 voor de roeier -->
      <origin rpy="0 0 0" xyz="0.0 0.0 0.1"/>
      <inertia ixx="3.2" ixy="0" ixz="0" iyy="54.2" iyz="0" izz="57"/>
<!--      <inertia ixx="0.6" ixy="0" ixz="0" iyy="11" iyz="0" izz="11.8"/>  -->
    </inertial>
    <collision>
      <origin rpy="0 0 0" xyz="0.0 0.0   0.1"/>
      <geometry>
        <box size="3.0 0.7 0.2"/>
      </geometry>
    </collision>
    <visual>
      <!-- should be a nice skull shape including riggers-->
      <origin rpy="0 0 0" xyz="0.0 0.0   0.1"/>
      <geometry>
        <box size="3.0 0.7 0.2"/>
      </geometry>
    </visual>
  </link>

  <link name="starboard_rowlock">    
    <inertial>
      <mass value="1.0"/>
      <origin rpy="0.0 0 0" xyz="0.4 0.0 0.0"/>
      <inertia ixx="0.00017" ixy="0" ixz="0" iyy="0.00017" iyz="0" izz="0.00007"/>
    </inertial>
    <collision>
      <origin rpy="0.0 0 0" xyz="0.4 0.0   0.0"/>
      <geometry>
        <box size="1.02 0.02 1.04"/>
      </geometry>
    </collision>
    <visual>
      <origin rpy="0.0 0 0" xyz="0.4 0.0   0.0"/>
      <geometry>
        <box size="1.02 0.02 1.04"/>
      </geometry>
    </visual>
  </link>


  <transmission name="tran1">
    <type>transmission_interface/SimpleTransmission</type>
    <joint name="starboard_rowlock_joint">
      <hardwareInterface>hardware_interface/EffortJointInterface</hardwareInterface>
    </joint>
    <actuator name="motor1">
      <mechanicalReduction>1</mechanicalReduction>
    </actuator>
  </transmission>

</robot>
