<?xml version="1.0" encoding="utf-8"?>
<!-- =================================================================================== -->
<!-- |    This document was autogenerated by xacro from boot1.xacro                    | -->
<!-- |    EDITING THIS FILE BY HAND IS NOT RECOMMENDED                                 | -->
<!-- =================================================================================== -->
<robot name="myboat" xmlns:xacro="http://www.ros.org/wiki/xacro">
  <!-- Constants for robot dimensions -->
  <gazebo>
    <self_collide>1</self_collide>
  </gazebo>
  <!-- ros_control plugin -->
  <gazebo>
    <plugin filename="libgazebo_ros_control.so" name="gazebo_ros_control">
      <robotNamespace>/boot1</robotNamespace>
      <robotSimType>gazebo_ros_control/DefaultRobotHWSim</robotSimType>
    </plugin>
  </gazebo>
  <gazebo reference="skiff">
    <material>Gazebo/Grey</material>
  </gazebo>
  <gazebo reference="starboard_rowlock">
    <mu1>0.01</mu1>
    <mu2>0.01</mu2>
    <material>Gazebo/Red</material>
  </gazebo>
  <gazebo reference="port_rowlock">
    <mu1>0.01</mu1>
    <mu2>0.01</mu2>
    <material>Gazebo/Red</material>
  </gazebo>
  <gazebo reference="starboard_oar">
    <mu1>0.01</mu1>
    <mu2>0.01</mu2>
    <material>Gazebo/Green</material>
  </gazebo>
  <gazebo reference="port_oar">
    <mu1>0.01</mu1>
    <mu2>0.01</mu2>
    <material>Gazebo/Green</material>
  </gazebo>
  <gazebo reference="starboard_blade">
    <mu1>0.01</mu1>
    <mu2>0.01</mu2>
    <material>Gazebo/Indigo</material>
  </gazebo>
  <gazebo reference="port_blade">
    <mu1>0.01</mu1>
    <mu2>0.01</mu2>
    <material>Gazebo/Indigo</material>
  </gazebo>
  <material name="black">
    <color rgba="0.0 0.0 0.0 1.0"/>
  </material>
  <material name="blue">
    <color rgba="0.0 0.0 0.8 1.0"/>
  </material>
  <material name="green">
    <color rgba="0.0 0.8 0.0 1.0"/>
  </material>
  <material name="grey">
    <color rgba="0.2 0.2 0.2 1.0"/>
  </material>
  <material name="orange">
    <color rgba="1.0 0.423529411765 0.0392156862745 1.0"/>
  </material>
  <material name="brown">
    <color rgba="0.870588235294 0.811764705882 0.764705882353 1.0"/>
  </material>
  <material name="red">
    <color rgba="0.8 0.0 0.0 1.0"/>
  </material>
  <material name="white">
    <color rgba="1.0 1.0 1.0 1.0"/>
  </material>
  <joint name="starboard_rowlock_joint" type="revolute">
    <parent link="skiff"/>
    <child link="starboard_rowlock"/>
    <origin rpy="0.0  0.0 0.0" xyz="0.0 0.8 0.32"/>
    <axis xyz="0 0 1"/>
    <limit effort="2000.0" lower="-1.4" upper="1.4" velocity="1.0"/>
  </joint>
  <joint name="port_rowlock_joint" type="revolute">
    <parent link="skiff"/>
    <child link="port_rowlock"/>
    <origin rpy="0.0  0.0 0.0" xyz="0.0 -0.8 0.3"/>
    <axis xyz="0 0 1"/>
    <limit effort="2000.0" lower="-1.4" upper="1.4" velocity="1.0"/>
  </joint>
  <joint name="starboard_rowlock_oar_joint" type="revolute">
    <parent link="starboard_rowlock"/>
    <child link="starboard_oar"/>
    <origin rpy="0.0  1.57079632679 -1.57079632679" xyz="0.0 0.0   0.02"/>
    <axis xyz="0 1 0"/>
    <limit effort="1000.0" lower="-0.4" upper="0.0" velocity="1.0"/>
  </joint>
  <joint name="port_rowlock_oar_joint" type="revolute">
    <parent link="port_rowlock"/>
    <child link="port_oar"/>
    <origin rpy="0.0  1.57079632679 -1.57079632679" xyz="0.0 0.0   0.02"/>
    <axis xyz="0 1 0"/>
    <limit effort="1000.0" lower="0.0" upper="0.4" velocity="1.0"/>
  </joint>
  <joint name="starboard_blade_joint" type="revolute">
    <parent link="starboard_oar"/>
    <child link="starboard_blade"/>
    <origin rpy="0 0  0.0" xyz="0.0 0.0   -1.8"/>
    <axis xyz="0 1 0"/>
    <limit effort="1000.0" lower="-1.5" upper="-1.2" velocity="1.0"/>
  </joint>
  <joint name="port_blade_joint" type="revolute">
    <parent link="port_oar"/>
    <child link="port_blade"/>
    <origin rpy="0.0  0 0.0" xyz="0.0 0.0   1.8"/>
    <axis xyz="0 1 0"/>
    <limit effort="1000.0" lower="-2.0" upper="-1.7" velocity="1.0"/>
  </joint>
  <link name="base_link"/>
  <!-- Dummy for gazebo   -->
  <joint name="dummy" type="fixed">
    <parent link="base_link"/>
    <child link="skiff"/>
  </joint>
  <link name="skiff">
    <inertial>
      <mass value="15"/>
      <origin rpy="0 0 0" xyz="0.0 0.0 0.1"/>
      <inertia ixx="0.6" ixy="0" ixz="0" iyy="11" iyz="0" izz="11.8"/>
    </inertial>
    <collision>
      <origin rpy="0 0 0" xyz="0.0 0.0   0.1"/>
      <geometry>
        <box size="3.0 0.7 0.2"/>
      </geometry>
    </collision>
    <visual>
      <!-- should be a nice skull shape including riggers-->
      <origin rpy="0 0 0" xyz="0.0 0.0   0.1"/>
      <geometry>
        <box size="3.0 0.7 0.2"/>
      </geometry>
    </visual>
  </link>
  <link name="starboard_rowlock">
    <inertial>
      <mass value="0.1"/>
      <origin rpy="0 0 0" xyz="0.0 0.0 0.0"/>
      <inertia ixx="0.00007" ixy="0" ixz="0" iyy="0.00007" iyz="0" izz="0.000007"/>
    </inertial>
    <collision>
      <origin rpy="0 0 0" xyz="0.0 0.0   0.0"/>
      <geometry>
        <box size="0.02 0.02 0.04"/>
      </geometry>
    </collision>
    <visual>
      <origin rpy="0 0 0" xyz="0.0 0.0   0.0"/>
      <geometry>
        <box size="0.02 0.02 0.04"/>
      </geometry>
    </visual>
  </link>
  <link name="port_rowlock">
    <inertial>
      <mass value="0.1"/>
      <origin rpy="0 0 0" xyz="0.0 0.0 0.0"/>
      <inertia ixx="0.00007" ixy="0" ixz="0" iyy="0.00007" iyz="0" izz="0.000007"/>
    </inertial>
    <collision>
      <origin rpy="0 0 0" xyz="0.0 0.0   0.0"/>
      <geometry>
        <box size="0.02 0.02 0.04"/>
      </geometry>
    </collision>
    <visual>
      <origin rpy="0 0 0" xyz="0.0 0.0   0.0"/>
      <geometry>
        <box size="0.02 0.02 0.04"/>
      </geometry>
    </visual>
  </link>
  <link name="starboard_oar">
    <inertial>
      <mass value="1.0"/>
      <origin rpy="0 0 0" xyz="0 0 -0.45"/>
      <inertia ixx="0.6" ixy="0" ixz="0" iyy="0.6" iyz="0" izz="0.001"/>
    </inertial>
    <collision>
      <origin rpy="0 0 0" xyz="0   0   -0.45"/>
      <geometry>
        <cylinder length="2.7" radius="0.02"/>
      </geometry>
    </collision>
    <visual>
      <origin rpy="0 0 0" xyz="0   0.0   -0.45"/>
      <geometry>
        <cylinder length="2.7" radius="0.02"/>
      </geometry>
    </visual>
  </link>
  <link name="port_oar">
    <inertial>
      <mass value="1.0"/>
      <origin rpy="0 0 0" xyz="0 0 0.45"/>
      <inertia ixx="0.6" ixy="0" ixz="0" iyy="0.6" iyz="0" izz="0.001"/>
    </inertial>
    <collision>
      <origin rpy="0 0 0" xyz="0   0   0.45"/>
      <geometry>
        <cylinder length="2.7" radius="0.02"/>
      </geometry>
    </collision>
    <visual>
      <origin rpy="0 0 0" xyz="0   0   0.45"/>
      <geometry>
        <cylinder length="2.7" radius="0.02"/>
      </geometry>
    </visual>
  </link>
  <link name="starboard_blade">
    <inertial>
      <mass value="1.0"/>
      <origin rpy="0 0 0" xyz="0 0 -0.01"/>
      <inertia ixx="0.34" ixy="0" ixz="0" iyy="0.34" iyz="0" izz="0.73"/>
    </inertial>
    <collision>
      <origin rpy="0 0 0" xyz="0    0   -0.01"/>
      <geometry>
        <box size="0.1 0.1 0.02"/>
      </geometry>
    </collision>
    <visual>
      <origin rpy="0 0 0" xyz="0    0   -0.01"/>
      <geometry>
        <box size="0.2 0.1 0.02"/>
      </geometry>
    </visual>
  </link>
  <link name="port_blade">
    <inertial>
      <mass value="1.0"/>
      <origin rpy="0 0 0" xyz="0 0 -0.01"/>
      <inertia ixx="0.34" ixy="0" ixz="0" iyy="0.34" iyz="0" izz="0.73"/>
    </inertial>
    <collision>
      <origin rpy="0 0 0" xyz="0    0   -0.01"/>
      <geometry>
        <box size="0.1 0.1 0.02"/>
      </geometry>
    </collision>
    <visual>
      <origin rpy="0 0 0" xyz="0    0.0   -0.01"/>
      <geometry>
        <box size="0.2 0.1 0.02"/>
      </geometry>
    </visual>
  </link>
  <transmission name="tran1">
    <type>transmission_interface/SimpleTransmission</type>
    <joint name="starboard_rowlock_joint">
      <hardwareInterface>hardware_interface/EffortJointInterface</hardwareInterface>
    </joint>
    <actuator name="motor1">
      <mechanicalReduction>1</mechanicalReduction>
    </actuator>
  </transmission>
  <transmission name="tran2">
    <type>transmission_interface/SimpleTransmission</type>
    <joint name="port_rowlock_joint">
      <hardwareInterface>hardware_interface/EffortJointInterface</hardwareInterface>
    </joint>
    <actuator name="motor2">
      <mechanicalReduction>1</mechanicalReduction>
    </actuator>
  </transmission>
  <transmission name="tran3">
    <type>transmission_interface/SimpleTransmission</type>
    <joint name="starboard_rowlock_oar_joint">
      <hardwareInterface>hardware_interface/EffortJointInterface</hardwareInterface>
    </joint>
    <actuator name="motor3">
      <mechanicalReduction>1</mechanicalReduction>
    </actuator>
  </transmission>
  <transmission name="tran4">
    <type>transmission_interface/SimpleTransmission</type>
    <joint name="port_rowlock_oar_joint">
      <hardwareInterface>hardware_interface/EffortJointInterface</hardwareInterface>
    </joint>
    <actuator name="motor4">
      <mechanicalReduction>1</mechanicalReduction>
    </actuator>
  </transmission>
  <transmission name="tran5">
    <type>transmission_interface/SimpleTransmission</type>
    <joint name="starboard_blade_joint">
      <hardwareInterface>hardware_interface/EffortJointInterface</hardwareInterface>
    </joint>
    <actuator name="motor5">
      <mechanicalReduction>1</mechanicalReduction>
    </actuator>
  </transmission>
  <transmission name="tran6">
    <type>transmission_interface/SimpleTransmission</type>
    <joint name="port_blade_joint">
      <hardwareInterface>hardware_interface/EffortJointInterface</hardwareInterface>
    </joint>
    <actuator name="motor6">
      <mechanicalReduction>1</mechanicalReduction>
    </actuator>
  </transmission>
</robot>

