<sdf version='1.6'>
  <model name='myboat'>
    <link name='base_link'>
      <pose frame=''>0 0 0 0 -0 0</pose>
      <inertial>
        <pose frame=''>0 0 0.1 0 -0 0</pose>
        <mass>15</mass>
        <inertia>
          <ixx>0.6</ixx>
          <ixy>0</ixy>
          <ixz>0</ixz>
          <iyy>11</iyy>
          <iyz>0</iyz>
          <izz>11.8</izz>
        </inertia>
      </inertial>
      <collision name='base_link_fixed_joint_lump__skiff_collision'>
        <pose frame=''>0 0 0.1 0 -0 0</pose>
        <geometry>
          <box>
            <size>3 0.7 0.2</size>
          </box>
        </geometry>
        <surface>
          <contact>
            <ode/>
          </contact>
          <friction>
            <ode/>
          </friction>
        </surface>
      </collision>
      <visual name='base_link_fixed_joint_lump__skiff_visual'>
        <pose frame=''>0 0 0.1 0 -0 0</pose>
        <geometry>
          <box>
            <size>3 0.7 0.2</size>
          </box>
        </geometry>
        <material>
          <script>
            <name>Gazebo/Grey</name>
            <uri>file://media/materials/scripts/gazebo.material</uri>
          </script>
        </material>
      </visual>
      <gravity>1</gravity>
      <velocity_decay/>
    </link>
    <link name='port_rowlock'>
      <pose frame=''>0 -0.8 0.3 0 -0 0</pose>
      <inertial>
        <pose frame=''>0 0 0 0 -0 0</pose>
        <mass>0.1</mass>
        <inertia>
          <ixx>7e-05</ixx>
          <ixy>0</ixy>
          <ixz>0</ixz>
          <iyy>7e-05</iyy>
          <iyz>0</iyz>
          <izz>7e-06</izz>
        </inertia>
      </inertial>
      <collision name='port_rowlock_collision'>
        <pose frame=''>0 0 0 0 -0 0</pose>
        <geometry>
          <box>
            <size>0.02 0.02 0.04</size>
          </box>
        </geometry>
        <surface>
          <contact>
            <ode/>
          </contact>
          <friction>
            <ode>
              <mu>0.01</mu>
              <mu2>0.01</mu2>
            </ode>
          </friction>
        </surface>
      </collision>
      <visual name='port_rowlock_visual'>
        <pose frame=''>0 0 0 0 -0 0</pose>
        <geometry>
          <box>
            <size>0.02 0.02 0.04</size>
          </box>
        </geometry>
        <material>
          <script>
            <name>Gazebo/Red</name>
            <uri>file://media/materials/scripts/gazebo.material</uri>
          </script>
        </material>
      </visual>
      <gravity>1</gravity>
      <velocity_decay/>
    </link>
    <joint name='port_rowlock_joint' type='revolute'>
      <child>port_rowlock</child>
      <parent>base_link</parent>
      <axis>
        <xyz>0 0 1</xyz>
        <limit>
          <lower>-1.4</lower>
          <upper>1.4</upper>
          <effort>2000</effort>
          <velocity>1</velocity>
        </limit>
        <dynamics>
          <spring_reference>0</spring_reference>
          <spring_stiffness>0</spring_stiffness>
        </dynamics>
        <use_parent_model_frame>1</use_parent_model_frame>
      </axis>
    </joint>
    <link name='port_oar'>
      <pose frame=''>0 -0.8 0.32 -1.57079 1.57079 3.14159</pose>
      <inertial>
        <pose frame=''>0 0 0.45 0 -0 0</pose>
        <mass>1</mass>
        <inertia>
          <ixx>0.6</ixx>
          <ixy>0</ixy>
          <ixz>0</ixz>
          <iyy>0.6</iyy>
          <iyz>0</iyz>
          <izz>0.001</izz>
        </inertia>
      </inertial>
      <collision name='port_oar_collision'>
        <pose frame=''>0 0 0.45 0 -0 0</pose>
        <geometry>
          <cylinder>
            <length>2.7</length>
            <radius>0.02</radius>
          </cylinder>
        </geometry>
        <surface>
          <contact>
            <ode/>
          </contact>
          <friction>
            <ode>
              <mu>0.01</mu>
              <mu2>0.01</mu2>
            </ode>
          </friction>
        </surface>
      </collision>
      <visual name='port_oar_visual'>
        <pose frame=''>0 0 0.45 0 -0 0</pose>
        <geometry>
          <cylinder>
            <length>2.7</length>
            <radius>0.02</radius>
          </cylinder>
        </geometry>
        <material>
          <script>
            <name>Gazebo/Green</name>
            <uri>file://media/materials/scripts/gazebo.material</uri>
          </script>
        </material>
      </visual>
      <gravity>1</gravity>
      <velocity_decay/>
    </link>
    <joint name='port_rowlock_oar_joint' type='revolute'>
      <child>port_oar</child>
      <parent>port_rowlock</parent>
      <axis>
        <xyz>1 0 -0</xyz>
        <limit>
          <lower>0</lower>
          <upper>0.4</upper>
          <effort>1000</effort>
          <velocity>1</velocity>
        </limit>
        <dynamics>
          <spring_reference>0</spring_reference>
          <spring_stiffness>0</spring_stiffness>
        </dynamics>
        <use_parent_model_frame>1</use_parent_model_frame>
      </axis>
    </joint>
    <link name='port_blade'>
      <pose frame=''>0 -2.6 0.32 -1.57079 1.57079 3.14159</pose>
      <inertial>
        <pose frame=''>0 0 -0.01 0 -0 0</pose>
        <mass>1</mass>
        <inertia>
          <ixx>0.34</ixx>
          <ixy>0</ixy>
          <ixz>0</ixz>
          <iyy>0.34</iyy>
          <iyz>0</iyz>
          <izz>0.73</izz>
        </inertia>
      </inertial>
      <collision name='port_blade_collision'>
        <pose frame=''>0 0 -0.01 0 -0 0</pose>
        <geometry>
          <box>
            <size>0.1 0.1 0.02</size>
          </box>
        </geometry>
        <surface>
          <contact>
            <ode/>
          </contact>
          <friction>
            <ode>
              <mu>0.01</mu>
              <mu2>0.01</mu2>
            </ode>
          </friction>
        </surface>
      </collision>
      <visual name='port_blade_visual'>
        <pose frame=''>0 0 -0.01 0 -0 0</pose>
        <geometry>
          <box>
            <size>0.2 0.1 0.02</size>
          </box>
        </geometry>
        <material>
          <script>
            <name>Gazebo/Indigo</name>
            <uri>file://media/materials/scripts/gazebo.material</uri>
          </script>
        </material>
      </visual>
      <gravity>1</gravity>
      <velocity_decay/>
    </link>
    <joint name='port_blade_joint' type='revolute'>
      <child>port_blade</child>
      <parent>port_oar</parent>
      <axis>
        <xyz>1 0 -0</xyz>
        <limit>
          <lower>-2</lower>
          <upper>-1.7</upper>
          <effort>1000</effort>
          <velocity>1</velocity>
        </limit>
        <dynamics>
          <spring_reference>0</spring_reference>
          <spring_stiffness>0</spring_stiffness>
        </dynamics>
        <use_parent_model_frame>1</use_parent_model_frame>
      </axis>
    </joint>
    <link name='starboard_rowlock'>
      <pose frame=''>0 0.8 0.32 0 -0 0</pose>
      <inertial>
        <pose frame=''>0 0 0 0 -0 0</pose>
        <mass>0.1</mass>
        <inertia>
          <ixx>7e-05</ixx>
          <ixy>0</ixy>
          <ixz>0</ixz>
          <iyy>7e-05</iyy>
          <iyz>0</iyz>
          <izz>7e-06</izz>
        </inertia>
      </inertial>
      <collision name='starboard_rowlock_collision'>
        <pose frame=''>0 0 0 0 -0 0</pose>
        <geometry>
          <box>
            <size>0.02 0.02 0.04</size>
          </box>
        </geometry>
        <surface>
          <contact>
            <ode/>
          </contact>
          <friction>
            <ode>
              <mu>0.01</mu>
              <mu2>0.01</mu2>
            </ode>
          </friction>
        </surface>
      </collision>
      <visual name='starboard_rowlock_visual'>
        <pose frame=''>0 0 0 0 -0 0</pose>
        <geometry>
          <box>
            <size>0.02 0.02 0.04</size>
          </box>
        </geometry>
        <material>
          <script>
            <name>Gazebo/Red</name>
            <uri>file://media/materials/scripts/gazebo.material</uri>
          </script>
        </material>
      </visual>
      <gravity>1</gravity>
      <velocity_decay/>
    </link>
    <joint name='starboard_rowlock_joint' type='revolute'>
      <child>starboard_rowlock</child>
      <parent>base_link</parent>
      <axis>
        <xyz>0 0 1</xyz>
        <limit>
          <lower>-1.4</lower>
          <upper>1.4</upper>
          <effort>2000</effort>
          <velocity>1</velocity>
        </limit>
        <dynamics>
          <spring_reference>0</spring_reference>
          <spring_stiffness>0</spring_stiffness>
        </dynamics>
        <use_parent_model_frame>1</use_parent_model_frame>
      </axis>
    </joint>
    <link name='starboard_oar'>
      <pose frame=''>0 0.8 0.34 -1.57079 1.57079 3.14159</pose>
      <inertial>
        <pose frame=''>0 0 -0.45 0 -0 0</pose>
        <mass>1</mass>
        <inertia>
          <ixx>0.6</ixx>
          <ixy>0</ixy>
          <ixz>0</ixz>
          <iyy>0.6</iyy>
          <iyz>0</iyz>
          <izz>0.001</izz>
        </inertia>
      </inertial>
      <collision name='starboard_oar_collision'>
        <pose frame=''>0 0 -0.45 0 -0 0</pose>
        <geometry>
          <cylinder>
            <length>2.7</length>
            <radius>0.02</radius>
          </cylinder>
        </geometry>
        <surface>
          <contact>
            <ode/>
          </contact>
          <friction>
            <ode>
              <mu>0.01</mu>
              <mu2>0.01</mu2>
            </ode>
          </friction>
        </surface>
      </collision>
      <visual name='starboard_oar_visual'>
        <pose frame=''>0 0 -0.45 0 -0 0</pose>
        <geometry>
          <cylinder>
            <length>2.7</length>
            <radius>0.02</radius>
          </cylinder>
        </geometry>
        <material>
          <script>
            <name>Gazebo/Green</name>
            <uri>file://media/materials/scripts/gazebo.material</uri>
          </script>
        </material>
      </visual>
      <gravity>1</gravity>
      <velocity_decay/>
    </link>
    <joint name='starboard_rowlock_oar_joint' type='revolute'>
      <child>starboard_oar</child>
      <parent>starboard_rowlock</parent>
      <axis>
        <xyz>1 0 -0</xyz>
        <limit>
          <lower>-0.4</lower>
          <upper>0</upper>
          <effort>1000</effort>
          <velocity>1</velocity>
        </limit>
        <dynamics>
          <spring_reference>0</spring_reference>
          <spring_stiffness>0</spring_stiffness>
        </dynamics>
        <use_parent_model_frame>1</use_parent_model_frame>
      </axis>
    </joint>
    <link name='starboard_blade'>
      <pose frame=''>-0 2.6 0.34 -1.57079 1.57079 3.14159</pose>
      <inertial>
        <pose frame=''>0 0 -0.01 0 -0 0</pose>
        <mass>1</mass>
        <inertia>
          <ixx>0.34</ixx>
          <ixy>0</ixy>
          <ixz>0</ixz>
          <iyy>0.34</iyy>
          <iyz>0</iyz>
          <izz>0.73</izz>
        </inertia>
      </inertial>
      <collision name='starboard_blade_collision'>
        <pose frame=''>0 0 -0.01 0 -0 0</pose>
        <geometry>
          <box>
            <size>0.1 0.1 0.02</size>
          </box>
        </geometry>
        <surface>
          <contact>
            <ode/>
          </contact>
          <friction>
            <ode>
              <mu>0.01</mu>
              <mu2>0.01</mu2>
            </ode>
          </friction>
        </surface>
      </collision>
      <visual name='starboard_blade_visual'>
        <pose frame=''>0 0 -0.01 0 -0 0</pose>
        <geometry>
          <box>
            <size>0.2 0.1 0.02</size>
          </box>
        </geometry>
        <material>
          <script>
            <name>Gazebo/Indigo</name>
            <uri>file://media/materials/scripts/gazebo.material</uri>
          </script>
        </material>
      </visual>
      <gravity>1</gravity>
      <velocity_decay/>
    </link>
    <joint name='starboard_blade_joint' type='revolute'>
      <child>starboard_blade</child>
      <parent>starboard_oar</parent>
      <axis>
        <xyz>1 0 -0</xyz>
        <limit>
          <lower>-1.5</lower>
          <upper>-1.2</upper>
          <effort>1000</effort>
          <velocity>1</velocity>
        </limit>
        <dynamics>
          <spring_reference>0</spring_reference>
          <spring_stiffness>0</spring_stiffness>
        </dynamics>
        <use_parent_model_frame>1</use_parent_model_frame>
      </axis>
    </joint>
    <self_collide>1</self_collide>
    <static>0</static>
    <plugin name='gazebo_ros_control' filename='libgazebo_ros_control.so'>
      <robotNamespace>/boot1</robotNamespace>
      <robotSimType>gazebo_ros_control/DefaultRobotHWSim</robotSimType>
    </plugin>
  </model>
</sdf>
