<?xml version="1.0" encoding="utf-8"?>
<!-- =================================================================================== -->
<!-- |    This document was autogenerated by xacro from boot2.xacro                    | -->
<!-- |    EDITING THIS FILE BY HAND IS NOT RECOMMENDED                                 | -->
<!-- =================================================================================== -->
<robot name="myboat" xmlns:xacro="http://www.ros.org/wiki/xacro">
  <!-- Constants for robot dimensions -->
  <gazebo>
    <self_collide>1</self_collide>
  </gazebo>
  <!-- ros_control plugin -->
  <gazebo>
    <plugin filename="libgazebo_ros_control.so" name="gazebo_ros_control">
      <robotNamespace>/boot2</robotNamespace>
      <robotSimType>gazebo_ros_control/DefaultRobotHWSim</robotSimType>
    </plugin>
    <plugin filename="libgazebo_ros_ft_sensor.so" name="sb_rl_sensor">
      <updateRate>50.0</updateRate>
      <topicName>sb_rl_sensor</topicName>
      <jointName>starboard_rowlock</jointName>
    </plugin>
    <plugin filename="libgazebo_ros_ft_sensor.so" name="p_rl_sensor">
      <updateRate>50.0</updateRate>
      <topicName>p_rl_sensor</topicName>
      <jointName>port_rowlock</jointName>
    </plugin>
    <plugin filename="libgazebo_ros_ft_sensor.so" name="sb_oar_sensor">
      <updateRate>50.0</updateRate>
      <topicName>sb_oar_sensor</topicName>
      <jointName>starboard_oar</jointName>
    </plugin>
    <plugin filename="libgazebo_ros_ft_sensor.so" name="p_oar_sensor">
      <updateRate>50.0</updateRate>
      <topicName>p_oar_sensor</topicName>
      <jointName>port_oar</jointName>
      <noise>
        <type>gaussian</type>
        <mean>0.0</mean>
        <stddev>0.003</stddev>
        <!-- change this to simulate noise -->
      </noise>
    </plugin>
    <plugin filename="libgazebo_ros_ft_sensor.so" name="sbb_sensor">
      <updateRate>50.0</updateRate>
      <topicName>sbb_sensor</topicName>
      <jointName>starboard_blade</jointName>
    </plugin>
    <plugin filename="libgazebo_ros_ft_sensor.so" name="pb_sensor">
      <updateRate>50.0</updateRate>
      <topicName>pb_sensor</topicName>
      <jointName>port_blade</jointName>
    </plugin>
  </gazebo>
  <gazebo reference="starboard_rowlock">
    <provideFeedback>true</provideFeedback>
  </gazebo>
  <gazebo reference="port_rowlock">
    <provideFeedback>true</provideFeedback>
  </gazebo>
  <gazebo reference="starboard_oar">
    <provideFeedback>true</provideFeedback>
  </gazebo>
  <gazebo reference="port_oar">
    <provideFeedback>true</provideFeedback>
  </gazebo>
  <gazebo reference="starboard_blade">
    <provideFeedback>true</provideFeedback>
  </gazebo>
  <gazebo reference="port_blade">
    <provideFeedback>true</provideFeedback>
  </gazebo>
  <gazebo reference="skiff">
    <material>Gazebo/White</material>
    <mu1>0.02</mu1>
    <mu2>0.02</mu2>
  </gazebo>
  <gazebo reference="starboard_rowlock_l">
    <mu1>0.01</mu1>
    <mu2>0.01</mu2>
    <material>Gazebo/Green</material>
  </gazebo>
  <gazebo reference="port_rowlock_l">
    <mu1>0.01</mu1>
    <mu2>0.01</mu2>
    <material>Gazebo/Red</material>
    <provideFeedback>true</provideFeedback>
  </gazebo>
  <gazebo reference="starboard_oar_l">
    <mu1>0.01</mu1>
    <mu2>0.01</mu2>
    <material>Gazebo/Green</material>
    <provideFeedback>true</provideFeedback>
  </gazebo>
  <gazebo reference="port_oar_l">
    <mu1>0.01</mu1>
    <mu2>0.01</mu2>
    <material>Gazebo/Green</material>
    <provideFeedback>true</provideFeedback>
  </gazebo>
  <gazebo reference="starboard_blade_l">
    <mu1>10.0</mu1>
    <mu2>10.0</mu2>
    <material>Gazebo/Green</material>
    <provideFeedback>true</provideFeedback>
  </gazebo>
  <gazebo reference="port_blade_l">
    <mu1>10.0</mu1>
    <mu2>10.0</mu2>
    <material>Gazebo/Red</material>
    <provideFeedback>true</provideFeedback>
  </gazebo>
  <material name="black">
    <color rgba="0.0 0.0 0.0 1.0"/>
  </material>
  <material name="blue">
    <color rgba="0.0 0.0 0.8 1.0"/>
  </material>
  <material name="green">
    <color rgba="0.0 0.8 0.0 1.0"/>
  </material>
  <material name="grey">
    <color rgba="0.2 0.2 0.2 1.0"/>
  </material>
  <material name="orange">
    <color rgba="1.0 0.423529411765 0.0392156862745 1.0"/>
  </material>
  <material name="brown">
    <color rgba="0.870588235294 0.811764705882 0.764705882353 1.0"/>
  </material>
  <material name="red">
    <color rgba="0.8 0.0 0.0 1.0"/>
  </material>
  <material name="white">
    <color rgba="1.0 1.0 1.0 1.0"/>
  </material>
  <!--
    Describes parameters of the boot model
-->
  <!--
 lengths of links, musle power?
-->
  <joint name="prism" type="prismatic">
    <parent link="world"/>
    <child link="l1"/>
    <origin rpy="0 0 0" xyz="0 0 0.25"/>
    <axis xyz="1 0 0"/>
    <limit effort="1000.0" lower="-1000" upper="1000" velocity="0.5"/>
  </joint>
  <joint name="rev1" type="revolute">
    <parent link="l1"/>
    <child link="l2"/>
    <origin rpy="0 1.57079632679 0" xyz="0.0 0 -0.2"/>
    <axis xyz="0 1 0"/>
    <limit effort="1000.0" lower="-1" upper="1" velocity="1.0"/>
  </joint>
  <joint name="rev2" type="revolute">
    <parent link="l2"/>
    <child link="skiff"/>
    <origin rpy="3.14159265359 1.57079632679 0" xyz="0.0 0.0 0.4"/>
    <axis xyz="0 1 0"/>
    <limit effort="1000.0" lower="-1" upper="1" velocity="1.0"/>
  </joint>
  <joint name="starboard_rowlock" type="revolute">
    <parent link="skiff"/>
    <child link="starboard_rowlock_l"/>
    <origin rpy="0.0  0.0 0.0" xyz="-3 0.8 0.42"/>
    <axis xyz="0 0 1"/>
    <limit effort="1000.0" lower="-1.4" upper="1.4" velocity="1.0"/>
  </joint>
  <joint name="port_rowlock" type="revolute">
    <parent link="skiff"/>
    <child link="port_rowlock_l"/>
    <origin rpy="0.0  0.0 0.0" xyz="-3 -0.8 0.4"/>
    <axis xyz="0 0 1"/>
    <limit effort="1000.0" lower="-1.4" upper="1.4" velocity="1.0"/>
  </joint>
  <joint name="starboard_oar" type="revolute">
    <parent link="starboard_rowlock_l"/>
    <child link="starboard_oar_l"/>
    <origin rpy="0.0  1.57079632679 -1.57079632679" xyz="0.0 0.0   0.02"/>
    <axis xyz="0 1 0"/>
    <limit effort="1000.0" lower="-0.4" upper="0.0" velocity="1.0"/>
  </joint>
  <joint name="port_oar" type="revolute">
    <parent link="port_rowlock_l"/>
    <child link="port_oar_l"/>
    <origin rpy="0.0  1.57079632679 -1.57079632679" xyz="0.0 0.0   0.02"/>
    <axis xyz="0 1 0"/>
    <limit effort="1000.0" lower="0.0" upper="0.4" velocity="1.0"/>
  </joint>
  <joint name="starboard_blade" type="revolute">
    <parent link="starboard_oar_l"/>
    <child link="starboard_blade_l"/>
    <origin rpy="0 0  0.0" xyz="0.0 0.0   -2.0"/>
    <axis xyz="0 1 0"/>
    <limit effort="1000.0" lower="-0.4" upper="0.4" velocity="1.0"/>
  </joint>
  <joint name="port_blade" type="revolute">
    <parent link="port_oar_l"/>
    <child link="port_blade_l"/>
    <origin rpy="0.0  0 0.0" xyz="0.0 0.0   2.0"/>
    <axis xyz="0 1 0"/>
    <limit effort="1000.0" lower="-0.4" upper="0.4" velocity="1.0"/>
  </joint>
  <link name="world"/>
  <link name="l1">
    <inertial>
      <mass value="0.01"/>
      <origin rpy="0 0 0" xyz="0 0.0 -0.1"/>
      <inertia ixx="0.006" ixy="0" ixz="0" iyy="0.1" iyz="0" izz="0.1"/>
    </inertial>
    <visual>
      <origin rpy="0 0 0" xyz="0.0 0.0 -0.1"/>
      <geometry>
        <box size="0.01 0.01 0.20"/>
      </geometry>
    </visual>
  </link>
  <link name="l2">
    <inertial>
      <mass value="0.01"/>
      <origin rpy="0 0 0" xyz="0 0.0 0.2"/>
      <inertia ixx="0.006" ixy="0" ixz="0" iyy="0.1" iyz="0" izz="0.1"/>
    </inertial>
    <visual>
      <origin rpy="0 0 0" xyz="0.0 0.0 0.2"/>
      <geometry>
        <box size="0.01 0.01 0.40"/>
      </geometry>
    </visual>
  </link>
  <link name="skiff">
    <inertial>
      <mass value="85"/>
      <!-- boat plus roeier -->
      <origin rpy="0 0 0" xyz="-3 0.0 0.05"/>
      <inertia ixx="3.2" ixy="0" ixz="0" iyy="54.2" iyz="0" izz="57"/>
      <!--      <inertia ixx="0.6" ixy="0" ixz="0" iyy="11" iyz="0" izz="11.8"/>  -->
    </inertial>
    <collision>
      <origin rpy="0 0 0" xyz="-3 0.0   0.05"/>
      <geometry>
        <box size="6.0 0.7 0.2"/>
      </geometry>
    </collision>
    <visual>
      <!-- should be a nice skull shape including riggers-->
      <origin rpy="0 0 0" xyz="-3 0.0   0.05"/>
      <geometry>
        <box size="6.0 0.7 0.2"/>
      </geometry>
    </visual>
  </link>
  <link name="starboard_rowlock_l">
    <inertial>
      <mass value="0.1"/>
      <origin rpy="0 0 0" xyz="0.0 0.0 0.0"/>
      <inertia ixx="0.000017" ixy="0" ixz="0" iyy="0.000017" iyz="0" izz="0.000007"/>
    </inertial>
    <collision>
      <origin rpy="0 0 0" xyz="0.0 0.0   0.0"/>
      <geometry>
        <box size="0.02 0.02 0.04"/>
      </geometry>
    </collision>
    <visual>
      <origin rpy="0 0 0" xyz="0.0 0.0   0.0"/>
      <geometry>
        <box size="0.02 0.02 0.04"/>
      </geometry>
    </visual>
  </link>
  <link name="port_rowlock_l">
    <inertial>
      <mass value="0.1"/>
      <origin rpy="0 0 0" xyz="0.0 0.0 0.0"/>
      <inertia ixx="0.000017" ixy="0" ixz="0" iyy="0.000017" iyz="0" izz="0.000007"/>
    </inertial>
    <collision>
      <origin rpy="0 0 0" xyz="0.0 0.0   0.0"/>
      <geometry>
        <box size="0.02 0.02 0.04"/>
      </geometry>
    </collision>
    <visual>
      <origin rpy="0 0 0" xyz="0.0 0.0   0.0"/>
      <geometry>
        <box size="0.02 0.02 0.04"/>
      </geometry>
    </visual>
  </link>
  <link name="starboard_oar_l">
    <inertial>
      <mass value="1.0"/>
      <origin rpy="0 0 0" xyz="0 0 -0.565"/>
      <inertia ixx="0.6" ixy="0" ixz="0" iyy="0.6" iyz="0" izz="0.001"/>
    </inertial>
    <collision>
      <origin rpy="0 0 0" xyz="0   0   -0.565"/>
      <geometry>
        <cylinder length="2.27" radius="0.02"/>
      </geometry>
    </collision>
    <visual>
      <origin rpy="0 0 0" xyz="0   0.0   -0.565"/>
      <geometry>
        <cylinder length="2.87" radius="0.02"/>
      </geometry>
    </visual>
  </link>
  <link name="port_oar_l">
    <inertial>
      <mass value="1.0"/>
      <origin rpy="0 0 0" xyz="0 0 0.565"/>
      <inertia ixx="0.6" ixy="0" ixz="0" iyy="0.6" iyz="0" izz="0.001"/>
    </inertial>
    <collision>
      <origin rpy="0 0 0" xyz="0   0   0.565"/>
      <geometry>
        <cylinder length="2.27" radius="0.02"/>
        <!-- -0.6 to prevent collissions  -->
      </geometry>
    </collision>
    <visual>
      <origin rpy="0 0 0" xyz="0   0   0.565"/>
      <geometry>
        <cylinder length="2.87" radius="0.02"/>
      </geometry>
    </visual>
  </link>
  <link name="starboard_blade_l">
    <inertial>
      <mass value="1.0"/>
      <origin rpy="0 -1.4 0" xyz="0.02 0 -0.02"/>
      <inertia ixx="0.0009" ixy="0" ixz="0" iyy="0.0034" iyz="0" izz="0.004"/>
    </inertial>
    <collision>
      <origin rpy="0 -1.4 0" xyz="0.02    0   -0.02"/>
      <geometry>
        <box size="0.2 0.1 0.03"/>
      </geometry>
    </collision>
    <visual>
      <origin rpy="0 -1.4 0" xyz="0.02    0   -0.02"/>
      <geometry>
        <box size="0.2 0.1 0.03"/>
      </geometry>
    </visual>
  </link>
  <link name="port_blade_l">
    <inertial>
      <mass value="1.0"/>
      <origin rpy="0 1.4 0" xyz="0.02 0 -0.02"/>
      <inertia ixx="0.0009" ixy="0" ixz="0" iyy="0.0034" iyz="0" izz="0.004"/>
    </inertial>
    <collision>
      <origin rpy="0 1.4 0" xyz="0.02    0   -0.02"/>
      <geometry>
        <box size="0.2 0.1 0.03"/>
      </geometry>
    </collision>
    <visual>
      <origin rpy="0 1.4 0" xyz="0.02    0.0  -0.02"/>
      <geometry>
        <box size="0.2 0.1 0.03"/>
      </geometry>
    </visual>
  </link>
  <transmission name="tran1">
    <type>transmission_interface/SimpleTransmission</type>
    <joint name="starboard_rowlock">
      <hardwareInterface>hardware_interface/EffortJointInterface</hardwareInterface>
    </joint>
    <actuator name="motor1">
      <mechanicalReduction>1</mechanicalReduction>
    </actuator>
  </transmission>
  <transmission name="tran2">
    <type>transmission_interface/SimpleTransmission</type>
    <joint name="port_rowlock">
      <hardwareInterface>hardware_interface/EffortJointInterface</hardwareInterface>
    </joint>
    <actuator name="motor2">
      <mechanicalReduction>1</mechanicalReduction>
    </actuator>
  </transmission>
  <transmission name="tran3">
    <type>transmission_interface/SimpleTransmission</type>
    <joint name="starboard_oar">
      <hardwareInterface>hardware_interface/EffortJointInterface</hardwareInterface>
    </joint>
    <actuator name="motor3">
      <mechanicalReduction>1</mechanicalReduction>
    </actuator>
  </transmission>
  <transmission name="tran4">
    <type>transmission_interface/SimpleTransmission</type>
    <joint name="port_oar">
      <hardwareInterface>hardware_interface/EffortJointInterface</hardwareInterface>
    </joint>
    <actuator name="motor4">
      <mechanicalReduction>1</mechanicalReduction>
    </actuator>
  </transmission>
  <transmission name="tran5">
    <type>transmission_interface/SimpleTransmission</type>
    <joint name="starboard_blade">
      <hardwareInterface>hardware_interface/EffortJointInterface</hardwareInterface>
    </joint>
    <actuator name="motor5">
      <mechanicalReduction>1</mechanicalReduction>
    </actuator>
  </transmission>
  <transmission name="tran6">
    <type>transmission_interface/SimpleTransmission</type>
    <joint name="port_blade">
      <hardwareInterface>hardware_interface/EffortJointInterface</hardwareInterface>
    </joint>
    <actuator name="motor6">
      <mechanicalReduction>1</mechanicalReduction>
    </actuator>
  </transmission>
</robot>

