<sdf version='1.6'>
  <model name='myboat'>
    <link name='l1'>
      <pose frame=''>0 0 0.25 0 -0 0</pose>
      <inertial>
        <pose frame=''>0 0 -0.1 0 -0 0</pose>
        <mass>0.01</mass>
        <inertia>
          <ixx>0.006</ixx>
          <ixy>0</ixy>
          <ixz>0</ixz>
          <iyy>0.1</iyy>
          <iyz>0</iyz>
          <izz>0.1</izz>
        </inertia>
      </inertial>
      <visual name='l1_visual'>
        <pose frame=''>0 0 -0.1 0 -0 0</pose>
        <geometry>
          <box>
            <size>0.01 0.01 0.2</size>
          </box>
        </geometry>
      </visual>
    </link>
    <joint name='prism' type='prismatic'>
      <child>l1</child>
      <parent>world</parent>
      <axis>
        <xyz>1 0 0</xyz>
        <limit>
          <lower>-1000</lower>
          <upper>1000</upper>
          <effort>1000</effort>
          <velocity>0.5</velocity>
        </limit>
        <dynamics>
          <spring_reference>0</spring_reference>
          <spring_stiffness>0</spring_stiffness>
        </dynamics>
        <use_parent_model_frame>1</use_parent_model_frame>
      </axis>
    </joint>
    <link name='l2'>
      <pose frame=''>0 0 0.05 3.14159 1.57079 3.14159</pose>
      <inertial>
        <pose frame=''>0 0 0.2 0 -0 0</pose>
        <mass>0.01</mass>
        <inertia>
          <ixx>0.006</ixx>
          <ixy>0</ixy>
          <ixz>0</ixz>
          <iyy>0.1</iyy>
          <iyz>0</iyz>
          <izz>0.1</izz>
        </inertia>
      </inertial>
      <visual name='l2_visual'>
        <pose frame=''>0 0 0.2 0 -0 0</pose>
        <geometry>
          <box>
            <size>0.01 0.01 0.4</size>
          </box>
        </geometry>
      </visual>
    </link>
    <joint name='rev1' type='revolute'>
      <child>l2</child>
      <parent>l1</parent>
      <axis>
        <xyz>0 1 0</xyz>
        <limit>
          <lower>-1</lower>
          <upper>1</upper>
          <effort>1000</effort>
          <velocity>1</velocity>
        </limit>
        <dynamics>
          <spring_reference>0</spring_reference>
          <spring_stiffness>0</spring_stiffness>
        </dynamics>
        <use_parent_model_frame>1</use_parent_model_frame>
      </axis>
    </joint>
    <link name='skiff'>
      <pose frame=''>0.4 0 0.05 0 0 3.14159</pose>
      <inertial>
        <pose frame=''>-3 0 0.05 0 -0 0</pose>
        <mass>75</mass>
        <inertia>
          <ixx>3.2</ixx>
          <ixy>0</ixy>
          <ixz>0</ixz>
          <iyy>54.2</iyy>
          <iyz>0</iyz>
          <izz>57</izz>
        </inertia>
      </inertial>
      <collision name='skiff_collision'>
        <pose frame=''>-3 0 0.05 0 -0 0</pose>
        <geometry>
          <box>
            <size>6 0.7 0.2</size>
          </box>
        </geometry>
        <surface>
          <contact>
            <ode/>
          </contact>
          <friction>
            <ode>
              <mu>0.01</mu>
              <mu2>0.01</mu2>
            </ode>
          </friction>
        </surface>
      </collision>
      <visual name='skiff_visual'>
        <pose frame=''>-3 0 0.05 0 -0 0</pose>
        <geometry>
          <box>
            <size>6 0.7 0.2</size>
          </box>
        </geometry>
        <material>
          <script>
            <name>Gazebo/Grey</name>
            <uri>file://media/materials/scripts/gazebo.material</uri>
          </script>
        </material>
      </visual>
      <gravity>1</gravity>
      <velocity_decay/>
    </link>
    <joint name='rev2' type='revolute'>
      <child>skiff</child>
      <parent>l2</parent>
      <axis>
        <xyz>-0 -1 0</xyz>
        <limit>
          <lower>-1</lower>
          <upper>1</upper>
          <effort>1000</effort>
          <velocity>1</velocity>
        </limit>
        <dynamics>
          <spring_reference>0</spring_reference>
          <spring_stiffness>0</spring_stiffness>
        </dynamics>
        <use_parent_model_frame>1</use_parent_model_frame>
      </axis>
    </joint>
    <link name='port_rowlock_l'>
      <pose frame=''>3.4 0.8 0.45 0 0 3.14159</pose>
      <inertial>
        <pose frame=''>0 0 0 0 -0 0</pose>
        <mass>0.1</mass>
        <inertia>
          <ixx>1.7e-05</ixx>
          <ixy>0</ixy>
          <ixz>0</ixz>
          <iyy>1.7e-05</iyy>
          <iyz>0</iyz>
          <izz>7e-06</izz>
        </inertia>
      </inertial>
      <collision name='port_rowlock_l_collision'>
        <pose frame=''>0 0 0 0 -0 0</pose>
        <geometry>
          <box>
            <size>0.02 0.02 0.04</size>
          </box>
        </geometry>
        <surface>
          <contact>
            <ode/>
          </contact>
          <friction>
            <ode>
              <mu>0.01</mu>
              <mu2>0.01</mu2>
            </ode>
          </friction>
        </surface>
      </collision>
      <visual name='port_rowlock_l_visual'>
        <pose frame=''>0 0 0 0 -0 0</pose>
        <geometry>
          <box>
            <size>0.02 0.02 0.04</size>
          </box>
        </geometry>
        <material>
          <script>
            <name>Gazebo/Red</name>
            <uri>file://media/materials/scripts/gazebo.material</uri>
          </script>
        </material>
      </visual>
      <gravity>1</gravity>
      <velocity_decay/>
    </link>
    <joint name='port_rowlock' type='revolute'>
      <child>port_rowlock_l</child>
      <parent>skiff</parent>
      <axis>
        <xyz>-0 0 1</xyz>
        <limit>
          <lower>-1.4</lower>
          <upper>1.4</upper>
          <effort>1000</effort>
          <velocity>1</velocity>
        </limit>
        <dynamics>
          <spring_reference>0</spring_reference>
          <spring_stiffness>0</spring_stiffness>
        </dynamics>
        <use_parent_model_frame>1</use_parent_model_frame>
      </axis>
      <physics>
        <provide_feedback>1</provide_feedback>
        <ode>
          <provide_feedback>1</provide_feedback>
          <limit>
            <cfm>0</cfm>
            <erp>0.2</erp>
          </limit>
        </ode>
      </physics>
    </joint>
    <link name='port_oar_l'>
      <pose frame=''>3.4 0.8 0.47 1.57079 1.57079 3.14159</pose>
      <inertial>
        <pose frame=''>0 0 0.45 0 -0 0</pose>
        <mass>1</mass>
        <inertia>
          <ixx>0.6</ixx>
          <ixy>0</ixy>
          <ixz>0</ixz>
          <iyy>0.6</iyy>
          <iyz>0</iyz>
          <izz>0.001</izz>
        </inertia>
      </inertial>
      <collision name='port_oar_l_collision'>
        <pose frame=''>0 0 0.45 0 -0 0</pose>
        <geometry>
          <cylinder>
            <length>2</length>
            <radius>0.02</radius>
          </cylinder>
        </geometry>
        <surface>
          <contact>
            <ode/>
          </contact>
          <friction>
            <ode>
              <mu>0.01</mu>
              <mu2>0.01</mu2>
            </ode>
          </friction>
        </surface>
      </collision>
      <visual name='port_oar_l_visual'>
        <pose frame=''>0 0 0.45 0 -0 0</pose>
        <geometry>
          <cylinder>
            <length>2.7</length>
            <radius>0.02</radius>
          </cylinder>
        </geometry>
        <material>
          <script>
            <name>Gazebo/Green</name>
            <uri>file://media/materials/scripts/gazebo.material</uri>
          </script>
        </material>
      </visual>
      <gravity>1</gravity>
      <velocity_decay/>
    </link>
    <joint name='port_oar' type='revolute'>
      <child>port_oar_l</child>
      <parent>port_rowlock_l</parent>
      <axis>
        <xyz>-1 -0 -0</xyz>
        <limit>
          <lower>0</lower>
          <upper>0.4</upper>
          <effort>1000</effort>
          <velocity>1</velocity>
        </limit>
        <dynamics>
          <spring_reference>0</spring_reference>
          <spring_stiffness>0</spring_stiffness>
        </dynamics>
        <use_parent_model_frame>1</use_parent_model_frame>
      </axis>
      <physics>
        <provide_feedback>1</provide_feedback>
        <ode>
          <provide_feedback>1</provide_feedback>
          <limit>
            <cfm>0</cfm>
            <erp>0.2</erp>
          </limit>
        </ode>
      </physics>
    </joint>
    <link name='port_blade_l'>
      <pose frame=''>3.4 2.6 0.47 1.57079 1.57079 3.14159</pose>
      <inertial>
        <pose frame=''>0.02 0 -0.02 0 1.4 0</pose>
        <mass>1</mass>
        <inertia>
          <ixx>0.0009</ixx>
          <ixy>0</ixy>
          <ixz>0</ixz>
          <iyy>0.0034</iyy>
          <iyz>0</iyz>
          <izz>0.004</izz>
        </inertia>
      </inertial>
      <collision name='port_blade_l_collision'>
        <pose frame=''>0.02 0 -0.02 0 1.4 0</pose>
        <geometry>
          <box>
            <size>0.2 0.1 0.03</size>
          </box>
        </geometry>
        <surface>
          <contact>
            <ode/>
          </contact>
          <friction>
            <ode>
              <mu>10</mu>
              <mu2>10</mu2>
            </ode>
          </friction>
        </surface>
      </collision>
      <visual name='port_blade_l_visual'>
        <pose frame=''>0.02 0 -0.02 0 1.4 0</pose>
        <geometry>
          <box>
            <size>0.2 0.1 0.03</size>
          </box>
        </geometry>
        <material>
          <script>
            <name>Gazebo/Red</name>
            <uri>file://media/materials/scripts/gazebo.material</uri>
          </script>
        </material>
      </visual>
      <gravity>1</gravity>
      <velocity_decay/>
    </link>
    <joint name='port_blade' type='revolute'>
      <child>port_blade_l</child>
      <parent>port_oar_l</parent>
      <axis>
        <xyz>-1 -0 -0</xyz>
        <limit>
          <lower>-0.4</lower>
          <upper>0.4</upper>
          <effort>1000</effort>
          <velocity>1</velocity>
        </limit>
        <dynamics>
          <spring_reference>0</spring_reference>
          <spring_stiffness>0</spring_stiffness>
        </dynamics>
        <use_parent_model_frame>1</use_parent_model_frame>
      </axis>
      <physics>
        <provide_feedback>1</provide_feedback>
        <ode>
          <provide_feedback>1</provide_feedback>
          <limit>
            <cfm>0</cfm>
            <erp>0.2</erp>
          </limit>
        </ode>
      </physics>
    </joint>
    <link name='starboard_rowlock_l'>
      <pose frame=''>3.4 -0.8 0.47 0 0 3.14159</pose>
      <inertial>
        <pose frame=''>0 0 0 0 -0 0</pose>
        <mass>0.1</mass>
        <inertia>
          <ixx>1.7e-05</ixx>
          <ixy>0</ixy>
          <ixz>0</ixz>
          <iyy>1.7e-05</iyy>
          <iyz>0</iyz>
          <izz>7e-06</izz>
        </inertia>
      </inertial>
      <collision name='starboard_rowlock_l_collision'>
        <pose frame=''>0 0 0 0 -0 0</pose>
        <geometry>
          <box>
            <size>0.02 0.02 0.04</size>
          </box>
        </geometry>
        <surface>
          <contact>
            <ode/>
          </contact>
          <friction>
            <ode>
              <mu>0.01</mu>
              <mu2>0.01</mu2>
            </ode>
          </friction>
        </surface>
      </collision>
      <visual name='starboard_rowlock_l_visual'>
        <pose frame=''>0 0 0 0 -0 0</pose>
        <geometry>
          <box>
            <size>0.02 0.02 0.04</size>
          </box>
        </geometry>
        <material>
          <script>
            <name>Gazebo/Green</name>
            <uri>file://media/materials/scripts/gazebo.material</uri>
          </script>
        </material>
      </visual>
      <gravity>1</gravity>
      <velocity_decay/>
    </link>
    <joint name='starboard_rowlock' type='revolute'>
      <child>starboard_rowlock_l</child>
      <parent>skiff</parent>
      <axis>
        <xyz>-0 0 1</xyz>
        <limit>
          <lower>-1.4</lower>
          <upper>1.4</upper>
          <effort>1000</effort>
          <velocity>1</velocity>
        </limit>
        <dynamics>
          <spring_reference>0</spring_reference>
          <spring_stiffness>0</spring_stiffness>
        </dynamics>
        <use_parent_model_frame>1</use_parent_model_frame>
      </axis>
      <physics>
        <provide_feedback>1</provide_feedback>
        <ode>
          <provide_feedback>1</provide_feedback>
          <limit>
            <cfm>0</cfm>
            <erp>0.2</erp>
          </limit>
        </ode>
      </physics>
    </joint>
    <link name='starboard_oar_l'>
      <pose frame=''>3.4 -0.8 0.49 1.57079 1.57079 3.14159</pose>
      <inertial>
        <pose frame=''>0 0 -0.45 0 -0 0</pose>
        <mass>1</mass>
        <inertia>
          <ixx>0.6</ixx>
          <ixy>0</ixy>
          <ixz>0</ixz>
          <iyy>0.6</iyy>
          <iyz>0</iyz>
          <izz>0.001</izz>
        </inertia>
      </inertial>
      <collision name='starboard_oar_l_collision'>
        <pose frame=''>0 0 -0.45 0 -0 0</pose>
        <geometry>
          <cylinder>
            <length>2</length>
            <radius>0.02</radius>
          </cylinder>
        </geometry>
        <surface>
          <contact>
            <ode/>
          </contact>
          <friction>
            <ode>
              <mu>0.01</mu>
              <mu2>0.01</mu2>
            </ode>
          </friction>
        </surface>
      </collision>
      <visual name='starboard_oar_l_visual'>
        <pose frame=''>0 0 -0.45 0 -0 0</pose>
        <geometry>
          <cylinder>
            <length>2.7</length>
            <radius>0.02</radius>
          </cylinder>
        </geometry>
        <material>
          <script>
            <name>Gazebo/Green</name>
            <uri>file://media/materials/scripts/gazebo.material</uri>
          </script>
        </material>
      </visual>
      <gravity>1</gravity>
      <velocity_decay/>
    </link>
    <joint name='starboard_oar' type='revolute'>
      <child>starboard_oar_l</child>
      <parent>starboard_rowlock_l</parent>
      <axis>
        <xyz>-1 -0 -0</xyz>
        <limit>
          <lower>-0.4</lower>
          <upper>0</upper>
          <effort>1000</effort>
          <velocity>1</velocity>
        </limit>
        <dynamics>
          <spring_reference>0</spring_reference>
          <spring_stiffness>0</spring_stiffness>
        </dynamics>
        <use_parent_model_frame>1</use_parent_model_frame>
      </axis>
      <physics>
        <provide_feedback>1</provide_feedback>
        <ode>
          <provide_feedback>1</provide_feedback>
          <limit>
            <cfm>0</cfm>
            <erp>0.2</erp>
          </limit>
        </ode>
      </physics>
    </joint>
    <link name='starboard_blade_l'>
      <pose frame=''>3.4 -2.6 0.49 1.57079 1.57079 3.14159</pose>
      <inertial>
        <pose frame=''>0.02 0 -0.02 0 -1.4 0</pose>
        <mass>1</mass>
        <inertia>
          <ixx>0.0009</ixx>
          <ixy>0</ixy>
          <ixz>0</ixz>
          <iyy>0.0034</iyy>
          <iyz>0</iyz>
          <izz>0.004</izz>
        </inertia>
      </inertial>
      <collision name='starboard_blade_l_collision'>
        <pose frame=''>0.02 0 -0.02 0 -1.4 0</pose>
        <geometry>
          <box>
            <size>0.2 0.1 0.03</size>
          </box>
        </geometry>
        <surface>
          <contact>
            <ode/>
          </contact>
          <friction>
            <ode>
              <mu>10</mu>
              <mu2>10</mu2>
            </ode>
          </friction>
        </surface>
      </collision>
      <visual name='starboard_blade_l_visual'>
        <pose frame=''>0.02 0 -0.02 0 -1.4 0</pose>
        <geometry>
          <box>
            <size>0.2 0.1 0.03</size>
          </box>
        </geometry>
        <material>
          <script>
            <name>Gazebo/Green</name>
            <uri>file://media/materials/scripts/gazebo.material</uri>
          </script>
        </material>
      </visual>
      <gravity>1</gravity>
      <velocity_decay/>
    </link>
    <joint name='starboard_blade' type='revolute'>
      <child>starboard_blade_l</child>
      <parent>starboard_oar_l</parent>
      <axis>
        <xyz>-1 -0 -0</xyz>
        <limit>
          <lower>-0.4</lower>
          <upper>0.4</upper>
          <effort>1000</effort>
          <velocity>1</velocity>
        </limit>
        <dynamics>
          <spring_reference>0</spring_reference>
          <spring_stiffness>0</spring_stiffness>
        </dynamics>
        <use_parent_model_frame>1</use_parent_model_frame>
      </axis>
      <physics>
        <provide_feedback>1</provide_feedback>
        <ode>
          <provide_feedback>1</provide_feedback>
          <limit>
            <cfm>0</cfm>
            <erp>0.2</erp>
          </limit>
        </ode>
      </physics>
    </joint>
    <self_collide>1</self_collide>
    <static>0</static>
    <plugin name='gazebo_ros_control' filename='libgazebo_ros_control.so'>
      <robotNamespace>/boot1</robotNamespace>
      <robotSimType>gazebo_ros_control/DefaultRobotHWSim</robotSimType>
    </plugin>
    <plugin name='sb_rl_sensor' filename='libgazebo_ros_ft_sensor.so'>
      <updateRate>10.0</updateRate>
      <topicName>sb_rl_sensor</topicName>
      <jointName>starboard_rowlock</jointName>
    </plugin>
    <plugin name='p_rl_sensor' filename='libgazebo_ros_ft_sensor.so'>
      <updateRate>10.0</updateRate>
      <topicName>p_rl_sensor</topicName>
      <jointName>port_rowlock</jointName>
    </plugin>
    <plugin name='sb_oar_sensor' filename='libgazebo_ros_ft_sensor.so'>
      <updateRate>10.0</updateRate>
      <topicName>sb_oar_sensor</topicName>
      <jointName>starboard_oar</jointName>
    </plugin>
    <plugin name='p_oar_sensor' filename='libgazebo_ros_ft_sensor.so'>
      <updateRate>10.0</updateRate>
      <topicName>p_oar_sensor</topicName>
      <jointName>port_oar</jointName>
      <noise>
        <type>gaussian</type>
        <mean>0.0</mean>
        <stddev>0.003</stddev>
      </noise>
    </plugin>
    <plugin name='sbb_sensor' filename='libgazebo_ros_ft_sensor.so'>
      <updateRate>10.0</updateRate>
      <topicName>sbb_sensor</topicName>
      <jointName>starboard_blade</jointName>
    </plugin>
    <plugin name='pb_sensor' filename='libgazebo_ros_ft_sensor.so'>
      <updateRate>10.0</updateRate>
      <topicName>pb_sensor</topicName>
      <jointName>port_blade</jointName>
    </plugin>
  </model>
</sdf>
