<?xml version="1.0" ?>

<robot name="myboat"  xmlns:xacro="http://www.ros.org/wiki/xacro">

  <!-- Constants for robot dimensions -->


  <!-- Import all Gazebo-customization elements, including Gazebo colors -->
  <xacro:include filename="$(find boot1_description)/urdf/boot1.gazebo" />
  <!-- Import Rviz colors -->
  <xacro:include filename="$(find boot1_description)/urdf/materials.xacro" />

  <joint name="prism" type="prismatic">
    <parent link="world"/>
    <child link="l1"/>
    <origin xyz="0 0 0.25" rpy="0 0 0"/>
    <axis xyz="1 0 0"/>
    <limit effort="1000.0" lower="-1000" upper="1000" velocity="0.5"/>
  </joint>

  <joint name="rev1" type="revolute">
    <parent link="l1"/>
    <child link="l2"/>
    <origin xyz="0.0 0 -0.2" rpy="0 ${pi/2} 0"/>
    <axis xyz="0 1 0"/>
    <limit effort="1000.0" lower="-1" upper="1" velocity="1.0"/>
  </joint>

  <joint name="rev2" type="revolute">
    <parent link="l2"/>
    <child link="skiff"/>
    <origin xyz="0.0 0.0 0.4" rpy="${pi} ${pi/2} 0"/>
    <axis xyz="0 1 0"/>
    <limit effort="1000.0" lower="-1" upper="1" velocity="1.0"/>
  </joint>

  <joint name="starboard_rowlock" type="revolute">
    <parent link="skiff"/>
    <child link="starboard_rowlock_l"/>
    <origin rpy="0.0  0.0 0.0" xyz="-3 0.8 0.42"/>
    <axis xyz="0 0 1"/>
    <limit effort="1000.0" lower="-1.4" upper="1.4" velocity="1.0"/>
  </joint>

  <joint name="port_rowlock" type="revolute">
    <parent link="skiff"/>
    <child link="port_rowlock_l"/>
    <origin rpy="0.0  0.0 0.0" xyz="-3 -0.8 0.4"/>
    <axis xyz="0 0 1"/>
    <limit effort="1000.0" lower="-1.4" upper="1.4" velocity="1.0"/>
  </joint>

  <joint name="starboard_oar" type="revolute">
    <parent link="starboard_rowlock_l"/>
    <child link="starboard_oar_l"/>
    <origin rpy="0.0  ${pi/2} -${pi/2}" xyz="0.0 0.0   0.02"/>
    <axis xyz="0 1 0"/>
    <limit effort="1000.0" lower="-0.4" upper="0.0" velocity="1.0"/>
  </joint>

  <joint name="port_oar" type="revolute">
    <parent link="port_rowlock_l"/>
    <child link="port_oar_l"/>
    <origin rpy="0.0  ${pi/2} -${pi/2}" xyz="0.0 0.0   0.02"/>
    <axis xyz="0 1 0"/>
    <limit effort="1000.0" lower="0.0" upper="0.4" velocity="1.0"/>
  </joint>

  <joint name="starboard_blade" type="revolute">
    <parent link="starboard_oar_l"/>
    <child link="starboard_blade_l"/>
    <origin rpy="0 0  0.0" xyz="0.0 0.0   -1.8"/>
    <axis xyz="0 1 0"/>
    <limit effort="1000.0" lower="-0.4" upper="0.4" velocity="1.0"/>
  </joint>

  <joint name="port_blade" type="revolute">
    <parent link="port_oar_l"/>
    <child link="port_blade_l"/>
    <origin rpy="0.0  0 0.0" xyz="0.0 0.0   1.8"/>
    <axis xyz="0 1 0"/>
    <limit effort="1000.0" lower="-0.4" upper="0.4" velocity="1.0"/>
  </joint>

  <link name="world"/>
  
  <link name="l1">
    <inertial>
      <mass value="0.01"/>
      <origin rpy="0 0 0" xyz="0 0.0 -0.1"/>
      <inertia ixx="0.006" ixy="0" ixz="0" iyy="0.1" iyz="0" izz="0.1"/> 
    </inertial>
    <visual>
      <origin rpy="0 0 0" xyz="0.0 0.0 -0.1"/>
      <geometry>
        <box size="0.01 0.01 0.20"/>
      </geometry>
    </visual>
  </link>

  <link name="l2">
    <inertial>
      <mass value="0.01"/>
      <origin rpy="0 0 0" xyz="0 0.0 0.2"/>
      <inertia ixx="0.006" ixy="0" ixz="0" iyy="0.1" iyz="0" izz="0.1"/> 
    </inertial>
    <visual>
      <origin rpy="0 0 0" xyz="0.0 0.0 0.2"/>
      <geometry>
        <box size="0.01 0.01 0.40"/>
      </geometry>
    </visual>
  </link>

  <link name="skiff">
    <inertial>
      <mass value="75"/>   <!-- 15 + 60 voor de roeier -->
      <origin rpy="0 0 0" xyz="-3 0.0 0.05"/>
      <inertia ixx="3.2" ixy="0" ixz="0" iyy="54.2" iyz="0" izz="57"/>
<!--      <inertia ixx="0.6" ixy="0" ixz="0" iyy="11" iyz="0" izz="11.8"/>  -->
    </inertial>
    <collision>
      <origin rpy="0 0 0" xyz="-3 0.0   0.05"/>
      <geometry>
        <box size="6.0 0.7 0.2"/>
      </geometry>
    </collision>
    <visual>
      <!-- should be a nice skull shape including riggers-->
      <origin rpy="0 0 0" xyz="-3 0.0   0.05"/>
      <geometry>
        <box size="6.0 0.7 0.2"/>
      </geometry>
    </visual>
  </link>

  <link name="starboard_rowlock_l">    
    <inertial>
      <mass value="0.1"/>
      <origin rpy="0 0 0" xyz="0.0 0.0 0.0"/>
      <inertia ixx="0.000017" ixy="0" ixz="0" iyy="0.000017" iyz="0" izz="0.000007"/>
    </inertial>
    <collision>
      <origin rpy="0 0 0" xyz="0.0 0.0   0.0"/>
      <geometry>
        <box size="0.02 0.02 0.04"/>
      </geometry>
    </collision>
    <visual>
      <origin rpy="0 0 0" xyz="0.0 0.0   0.0"/>
      <geometry>
        <box size="0.02 0.02 0.04"/>
      </geometry>
    </visual>
  </link>

  <link name="port_rowlock_l">    
    <inertial>
      <mass value="0.1"/>
      <origin rpy="0 0 0" xyz="0.0 0.0 0.0"/>
      <inertia ixx="0.000017" ixy="0" ixz="0" iyy="0.000017" iyz="0" izz="0.000007"/>
    </inertial>
    <collision>
      <origin rpy="0 0 0" xyz="0.0 0.0   0.0"/>
      <geometry>
        <box size="0.02 0.02 0.04"/>
      </geometry>
    </collision>
    <visual>
      <origin rpy="0 0 0" xyz="0.0 0.0   0.0"/>
      <geometry>
        <box size="0.02 0.02 0.04"/>
      </geometry>
    </visual>
  </link>

  <link name="starboard_oar_l">
    <inertial>
      <mass value="1.0"/>
      <origin rpy="0 0 0" xyz="0 0 -0.45"/>
      <inertia ixx="0.6" ixy="0" ixz="0" iyy="0.6" iyz="0" izz="0.001"/>	   
    </inertial>
    <collision>
      <origin rpy="0 0 0" xyz="0   0   -0.45"/>
      <geometry>
        <cylinder length="2.0" radius="0.02"/>
      </geometry>
    </collision>
    <visual>
      <origin rpy="0 0 0" xyz="0   0.0   -0.45"/>
      <geometry>
        <cylinder length="2.7" radius="0.02"/>
      </geometry>
    </visual>
  </link>

  <link name="port_oar_l">
    <inertial>
      <mass value="1.0"/>
      <origin rpy="0 0 0" xyz="0 0 0.45"/>
      <inertia ixx="0.6" ixy="0" ixz="0" iyy="0.6" iyz="0" izz="0.001"/>	   
    </inertial>
    <collision>
      <origin rpy="0 0 0" xyz="0   0   0.45"/>
      <geometry>
        <cylinder length="2.0" radius="0.02"/>  <!-- 2.0 to prevent collissions  -->
      </geometry>
    </collision>
    <visual>
      <origin rpy="0 0 0" xyz="0   0   0.45"/>
      <geometry>
        <cylinder length="2.7" radius="0.02"/>
      </geometry>
    </visual>
  </link>

  <link name="starboard_blade_l">
    <inertial>
      <mass value="1.0"/>
      <origin rpy="0 -1.4 0" xyz="0.02 0 -0.02"/>
      <inertia ixx="0.0009" ixy="0" ixz="0" iyy="0.0034" iyz="0" izz="0.004"/>
    </inertial>
    <collision>
      <origin rpy="0 -1.4 0" xyz="0.02    0   -0.02"/>
      <geometry>
        <box size="0.2 0.1 0.03"/>
      </geometry>
    </collision>
    <visual>
      <origin rpy="0 -1.4 0" xyz="0.02    0   -0.02"/>
      <geometry>
        <box size="0.2 0.1 0.03"/>
      </geometry>
    </visual>
  </link>

  <link name="port_blade_l">
    <inertial>
      <mass value="1.0"/>
      <origin rpy="0 1.4 0" xyz="0.02 0 -0.02"/>
      <inertia ixx="0.0009" ixy="0" ixz="0" iyy="0.0034" iyz="0" izz="0.004"/>
    </inertial>
    <collision>
      <origin rpy="0 1.4 0" xyz="0.02    0   -0.02"/>
      <geometry>
        <box size="0.2 0.1 0.03"/>
      </geometry>
    </collision>
    <visual>
      <origin rpy="0 1.4 0" xyz="0.02    0.0  -0.02"/>
      <geometry>
        <box size="0.2 0.1 0.03"/>
      </geometry>
    </visual>
  </link>

  <transmission name="tran1">
    <type>transmission_interface/SimpleTransmission</type>
    <joint name="starboard_rowlock">
      <hardwareInterface>hardware_interface/EffortJointInterface</hardwareInterface>
    </joint>
    <actuator name="motor1">
      <mechanicalReduction>1</mechanicalReduction>
    </actuator>
  </transmission>

  <transmission name="tran2">
    <type>transmission_interface/SimpleTransmission</type>
    <joint name="port_rowlock">
      <hardwareInterface>hardware_interface/EffortJointInterface</hardwareInterface>
    </joint>
    <actuator name="motor2">
      <mechanicalReduction>1</mechanicalReduction>
    </actuator>
  </transmission>

  <transmission name="tran3">
    <type>transmission_interface/SimpleTransmission</type>
    <joint name="starboard_oar">
      <hardwareInterface>hardware_interface/EffortJointInterface</hardwareInterface>
    </joint>
    <actuator name="motor3">
      <mechanicalReduction>1</mechanicalReduction>
    </actuator>
  </transmission>

  <transmission name="tran4">
    <type>transmission_interface/SimpleTransmission</type>
    <joint name="port_oar">
      <hardwareInterface>hardware_interface/EffortJointInterface</hardwareInterface>
    </joint>
    <actuator name="motor4">
      <mechanicalReduction>1</mechanicalReduction>
    </actuator>
  </transmission>

  <transmission name="tran5">
    <type>transmission_interface/SimpleTransmission</type>
    <joint name="starboard_blade">
      <hardwareInterface>hardware_interface/EffortJointInterface</hardwareInterface>
    </joint>
    <actuator name="motor5">
      <mechanicalReduction>1</mechanicalReduction>
    </actuator>
  </transmission>

  <transmission name="tran6">
    <type>transmission_interface/SimpleTransmission</type>
    <joint name="port_blade">
      <hardwareInterface>hardware_interface/EffortJointInterface</hardwareInterface>
    </joint>
    <actuator name="motor6">
      <mechanicalReduction>1</mechanicalReduction>
    </actuator>
  </transmission>




</robot>
